2018-05-16T01:08:06.8168552+02:00 0HLDQN2ILPFVL:00000001 [WRN] User "(null)" validation failed: "InvalidUserName". (5dc28e15)
2018-05-16T01:09:24.4384603+02:00 0HLDQN2ILPFVM:00000001 [WRN] User "(null)" validation failed: "InvalidUserName". (5dc28e15)
2018-05-16T01:10:21.6594644+02:00 0HLDQN2ILPFVN:00000001 [WRN] User "(null)" validation failed: "InvalidUserName". (5dc28e15)
2018-05-16T01:11:08.7485809+02:00 0HLDQN2ILPFVO:00000001 [WRN] The LINQ expression '"where {from String ui in {from IdentityUserRole`1 u in value(Microsoft.EntityFrameworkCore.Query.Internal.EntityQueryable`1[Microsoft.AspNetCore.Identity.IdentityUserRole`1[System.String]]) where ([u].RoleId == __roleGuardianId_0) select [u].UserId => Distinct()} where ([ui] == [u].Id) select [ui] => Any()}"' could not be translated and will be evaluated locally. (011792c6)
2018-05-16T01:32:30.8680250+02:00 0HLDQN2ILPG0H:00000007 [WRN] User "(null)" validation failed: "InvalidUserName". (5dc28e15)
2018-05-16T01:51:44.9487753+02:00 0HLDQN2ILPG13:00000001 [WRN] VerifyUserTokenAsync() failed with purpose: "ResetPassword" for user "18140de0-fe7f-469a-8876-59abedf384e4". (08c3f50e)
2018-05-16T10:59:40.2849839+02:00 0HLDR17906P4L:00000003 [ERR] An exception occurred in the database while iterating the results of a query for context type '"GirafRest.Data.GirafDbContext"'."
""System.OperationCanceledException: The operation was canceled.
   at System.Threading.CancellationToken.ThrowOperationCanceledException()
   at Microsoft.EntityFrameworkCore.Query.Internal.AsyncQueryingEnumerable`1.AsyncEnumerator.<MoveNext>d__9.MoveNext()
--- End of stack trace from previous location where exception was thrown ---
   at System.Runtime.ExceptionServices.ExceptionDispatchInfo.Throw()
   at System.Runtime.CompilerServices.TaskAwaiter.ThrowForNonSuccess(Task task)
   at System.Runtime.CompilerServices.TaskAwaiter.HandleNonSuccessAndDebuggerNotification(Task task)
   at System.Runtime.CompilerServices.ConfiguredTaskAwaitable`1.ConfiguredTaskAwaiter.GetResult()
   at System.Linq.AsyncEnumerable.<SingleOrDefault_>d__381`1.MoveNext()
--- End of stack trace from previous location where exception was thrown ---
   at System.Runtime.ExceptionServices.ExceptionDispatchInfo.Throw()
   at System.Runtime.CompilerServices.TaskAwaiter.ThrowForNonSuccess(Task task)
   at System.Runtime.CompilerServices.TaskAwaiter.HandleNonSuccessAndDebuggerNotification(Task task)
   at System.Runtime.CompilerServices.TaskAwaiter`1.GetResult()
   at Microsoft.EntityFrameworkCore.Query.Internal.AsyncLinqOperatorProvider.TaskResultAsyncEnumerable`1.Enumerator.<MoveNext>d__3.MoveNext()
--- End of stack trace from previous location where exception was thrown ---
   at System.Runtime.ExceptionServices.ExceptionDispatchInfo.Throw()
   at System.Runtime.CompilerServices.TaskAwaiter.ThrowForNonSuccess(Task task)
   at System.Runtime.CompilerServices.TaskAwaiter.HandleNonSuccessAndDebuggerNotification(Task task)
   at System.Runtime.CompilerServices.ConfiguredTaskAwaitable`1.ConfiguredTaskAwaiter.GetResult()
   at System.Linq.AsyncEnumerable.SelectEnumerableAsyncIterator`2.<MoveNextCore>d__7.MoveNext()
--- End of stack trace from previous location where exception was thrown ---
   at System.Runtime.ExceptionServices.ExceptionDispatchInfo.Throw()
   at System.Runtime.CompilerServices.TaskAwaiter.ThrowForNonSuccess(Task task)
   at System.Runtime.CompilerServices.TaskAwaiter.HandleNonSuccessAndDebuggerNotification(Task task)
   at System.Runtime.CompilerServices.ConfiguredTaskAwaitable`1.ConfiguredTaskAwaiter.GetResult()
   at System.Linq.AsyncEnumerable.AsyncIterator`1.<MoveNext>d__10.MoveNext()
--- End of stack trace from previous location where exception was thrown ---
   at System.Runtime.ExceptionServices.ExceptionDispatchInfo.Throw()
   at System.Runtime.CompilerServices.TaskAwaiter.ThrowForNonSuccess(Task task)
   at System.Runtime.CompilerServices.TaskAwaiter.HandleNonSuccessAndDebuggerNotification(Task task)
   at System.Runtime.CompilerServices.TaskAwaiter`1.GetResult()
   at Microsoft.EntityFrameworkCore.Query.Internal.AsyncLinqOperatorProvider.ExceptionInterceptor`1.EnumeratorExceptionInterceptor.<MoveNext>d__5.MoveNext()" (64e2593c)
System.OperationCanceledException: The operation was canceled.
   at System.Threading.CancellationToken.ThrowOperationCanceledException()
   at Microsoft.EntityFrameworkCore.Query.Internal.AsyncQueryingEnumerable`1.AsyncEnumerator.<MoveNext>d__9.MoveNext()
--- End of stack trace from previous location where exception was thrown ---
   at System.Runtime.ExceptionServices.ExceptionDispatchInfo.Throw()
   at System.Runtime.CompilerServices.TaskAwaiter.ThrowForNonSuccess(Task task)
   at System.Runtime.CompilerServices.TaskAwaiter.HandleNonSuccessAndDebuggerNotification(Task task)
   at System.Runtime.CompilerServices.ConfiguredTaskAwaitable`1.ConfiguredTaskAwaiter.GetResult()
   at System.Linq.AsyncEnumerable.<SingleOrDefault_>d__381`1.MoveNext()
--- End of stack trace from previous location where exception was thrown ---
   at System.Runtime.ExceptionServices.ExceptionDispatchInfo.Throw()
   at System.Runtime.CompilerServices.TaskAwaiter.ThrowForNonSuccess(Task task)
   at System.Runtime.CompilerServices.TaskAwaiter.HandleNonSuccessAndDebuggerNotification(Task task)
   at System.Runtime.CompilerServices.TaskAwaiter`1.GetResult()
   at Microsoft.EntityFrameworkCore.Query.Internal.AsyncLinqOperatorProvider.TaskResultAsyncEnumerable`1.Enumerator.<MoveNext>d__3.MoveNext()
--- End of stack trace from previous location where exception was thrown ---
   at System.Runtime.ExceptionServices.ExceptionDispatchInfo.Throw()
   at System.Runtime.CompilerServices.TaskAwaiter.ThrowForNonSuccess(Task task)
   at System.Runtime.CompilerServices.TaskAwaiter.HandleNonSuccessAndDebuggerNotification(Task task)
   at System.Runtime.CompilerServices.ConfiguredTaskAwaitable`1.ConfiguredTaskAwaiter.GetResult()
   at System.Linq.AsyncEnumerable.SelectEnumerableAsyncIterator`2.<MoveNextCore>d__7.MoveNext()
--- End of stack trace from previous location where exception was thrown ---
   at System.Runtime.ExceptionServices.ExceptionDispatchInfo.Throw()
   at System.Runtime.CompilerServices.TaskAwaiter.ThrowForNonSuccess(Task task)
   at System.Runtime.CompilerServices.TaskAwaiter.HandleNonSuccessAndDebuggerNotification(Task task)
   at System.Runtime.CompilerServices.ConfiguredTaskAwaitable`1.ConfiguredTaskAwaiter.GetResult()
   at System.Linq.AsyncEnumerable.AsyncIterator`1.<MoveNext>d__10.MoveNext()
--- End of stack trace from previous location where exception was thrown ---
   at System.Runtime.ExceptionServices.ExceptionDispatchInfo.Throw()
   at System.Runtime.CompilerServices.TaskAwaiter.ThrowForNonSuccess(Task task)
   at System.Runtime.CompilerServices.TaskAwaiter.HandleNonSuccessAndDebuggerNotification(Task task)
   at System.Runtime.CompilerServices.TaskAwaiter`1.GetResult()
   at Microsoft.EntityFrameworkCore.Query.Internal.AsyncLinqOperatorProvider.ExceptionInterceptor`1.EnumeratorExceptionInterceptor.<MoveNext>d__5.MoveNext()
--- End of stack trace from previous location where exception was thrown ---
   at System.Runtime.ExceptionServices.ExceptionDispatchInfo.Throw()
   at System.Runtime.CompilerServices.TaskAwaiter.ThrowForNonSuccess(Task task)
   at System.Runtime.CompilerServices.TaskAwaiter.HandleNonSuccessAndDebuggerNotification(Task task)
   at System.Runtime.CompilerServices.TaskAwaiter`1.GetResult()
   at Microsoft.EntityFrameworkCore.Query.Internal.QueryCompiler.<ExecuteSingletonAsyncQuery>d__23`1.MoveNext()
2018-05-16T10:59:40.4422555+02:00 0HLDR17906P4L:00000003 [ERR] An exception occurred in the database while iterating the results of a query for context type '"GirafRest.Data.GirafDbContext"'."
""System.OperationCanceledException: The operation was canceled.
   at System.Threading.CancellationToken.ThrowOperationCanceledException()
   at Microsoft.EntityFrameworkCore.Query.Internal.AsyncQueryingEnumerable`1.AsyncEnumerator.<MoveNext>d__9.MoveNext()
--- End of stack trace from previous location where exception was thrown ---
   at System.Runtime.ExceptionServices.ExceptionDispatchInfo.Throw()
   at System.Runtime.CompilerServices.TaskAwaiter.ThrowForNonSuccess(Task task)
   at System.Runtime.CompilerServices.TaskAwaiter.HandleNonSuccessAndDebuggerNotification(Task task)
   at System.Runtime.CompilerServices.ConfiguredTaskAwaitable`1.ConfiguredTaskAwaiter.GetResult()
   at System.Linq.AsyncEnumerable.<SingleOrDefault_>d__381`1.MoveNext()
--- End of stack trace from previous location where exception was thrown ---
   at System.Runtime.ExceptionServices.ExceptionDispatchInfo.Throw()
   at System.Runtime.CompilerServices.TaskAwaiter.ThrowForNonSuccess(Task task)
   at System.Runtime.CompilerServices.TaskAwaiter.HandleNonSuccessAndDebuggerNotification(Task task)
   at System.Runtime.CompilerServices.TaskAwaiter`1.GetResult()
   at Microsoft.EntityFrameworkCore.Query.Internal.AsyncLinqOperatorProvider.TaskResultAsyncEnumerable`1.Enumerator.<MoveNext>d__3.MoveNext()
--- End of stack trace from previous location where exception was thrown ---
   at System.Runtime.ExceptionServices.ExceptionDispatchInfo.Throw()
   at System.Runtime.CompilerServices.TaskAwaiter.ThrowForNonSuccess(Task task)
   at System.Runtime.CompilerServices.TaskAwaiter.HandleNonSuccessAndDebuggerNotification(Task task)
   at System.Runtime.CompilerServices.ConfiguredTaskAwaitable`1.ConfiguredTaskAwaiter.GetResult()
   at System.Linq.AsyncEnumerable.SelectEnumerableAsyncIterator`2.<MoveNextCore>d__7.MoveNext()
--- End of stack trace from previous location where exception was thrown ---
   at System.Runtime.ExceptionServices.ExceptionDispatchInfo.Throw()
   at System.Runtime.CompilerServices.TaskAwaiter.ThrowForNonSuccess(Task task)
   at System.Runtime.CompilerServices.TaskAwaiter.HandleNonSuccessAndDebuggerNotification(Task task)
   at System.Runtime.CompilerServices.ConfiguredTaskAwaitable`1.ConfiguredTaskAwaiter.GetResult()
   at System.Linq.AsyncEnumerable.AsyncIterator`1.<MoveNext>d__10.MoveNext()
--- End of stack trace from previous location where exception was thrown ---
   at System.Runtime.ExceptionServices.ExceptionDispatchInfo.Throw()
   at System.Runtime.CompilerServices.TaskAwaiter.ThrowForNonSuccess(Task task)
   at System.Runtime.CompilerServices.TaskAwaiter.HandleNonSuccessAndDebuggerNotification(Task task)
   at System.Runtime.CompilerServices.TaskAwaiter`1.GetResult()
   at Microsoft.EntityFrameworkCore.Query.Internal.AsyncLinqOperatorProvider.ExceptionInterceptor`1.EnumeratorExceptionInterceptor.<MoveNext>d__5.MoveNext()
--- End of stack trace from previous location where exception was thrown ---
   at System.Runtime.ExceptionServices.ExceptionDispatchInfo.Throw()
   at System.Runtime.CompilerServices.TaskAwaiter.ThrowForNonSuccess(Task task)
   at System.Runtime.CompilerServices.TaskAwaiter.HandleNonSuccessAndDebuggerNotification(Task task)
   at System.Runtime.CompilerServices.TaskAwaiter`1.GetResult()
   at Microsoft.EntityFrameworkCore.Query.Internal.QueryCompiler.<ExecuteSingletonAsyncQuery>d__23`1.MoveNext()" (64e2593c)
System.OperationCanceledException: The operation was canceled.
   at System.Threading.CancellationToken.ThrowOperationCanceledException()
   at Microsoft.EntityFrameworkCore.Query.Internal.AsyncQueryingEnumerable`1.AsyncEnumerator.<MoveNext>d__9.MoveNext()
--- End of stack trace from previous location where exception was thrown ---
   at System.Runtime.ExceptionServices.ExceptionDispatchInfo.Throw()
   at System.Runtime.CompilerServices.TaskAwaiter.ThrowForNonSuccess(Task task)
   at System.Runtime.CompilerServices.TaskAwaiter.HandleNonSuccessAndDebuggerNotification(Task task)
   at System.Runtime.CompilerServices.ConfiguredTaskAwaitable`1.ConfiguredTaskAwaiter.GetResult()
   at System.Linq.AsyncEnumerable.<SingleOrDefault_>d__381`1.MoveNext()
--- End of stack trace from previous location where exception was thrown ---
   at System.Runtime.ExceptionServices.ExceptionDispatchInfo.Throw()
   at System.Runtime.CompilerServices.TaskAwaiter.ThrowForNonSuccess(Task task)
   at System.Runtime.CompilerServices.TaskAwaiter.HandleNonSuccessAndDebuggerNotification(Task task)
   at System.Runtime.CompilerServices.TaskAwaiter`1.GetResult()
   at Microsoft.EntityFrameworkCore.Query.Internal.AsyncLinqOperatorProvider.TaskResultAsyncEnumerable`1.Enumerator.<MoveNext>d__3.MoveNext()
--- End of stack trace from previous location where exception was thrown ---
   at System.Runtime.ExceptionServices.ExceptionDispatchInfo.Throw()
   at System.Runtime.CompilerServices.TaskAwaiter.ThrowForNonSuccess(Task task)
   at System.Runtime.CompilerServices.TaskAwaiter.HandleNonSuccessAndDebuggerNotification(Task task)
   at System.Runtime.CompilerServices.ConfiguredTaskAwaitable`1.ConfiguredTaskAwaiter.GetResult()
   at System.Linq.AsyncEnumerable.SelectEnumerableAsyncIterator`2.<MoveNextCore>d__7.MoveNext()
--- End of stack trace from previous location where exception was thrown ---
   at System.Runtime.ExceptionServices.ExceptionDispatchInfo.Throw()
   at System.Runtime.CompilerServices.TaskAwaiter.ThrowForNonSuccess(Task task)
   at System.Runtime.CompilerServices.TaskAwaiter.HandleNonSuccessAndDebuggerNotification(Task task)
   at System.Runtime.CompilerServices.ConfiguredTaskAwaitable`1.ConfiguredTaskAwaiter.GetResult()
   at System.Linq.AsyncEnumerable.AsyncIterator`1.<MoveNext>d__10.MoveNext()
--- End of stack trace from previous location where exception was thrown ---
   at System.Runtime.ExceptionServices.ExceptionDispatchInfo.Throw()
   at System.Runtime.CompilerServices.TaskAwaiter.ThrowForNonSuccess(Task task)
   at System.Runtime.CompilerServices.TaskAwaiter.HandleNonSuccessAndDebuggerNotification(Task task)
   at System.Runtime.CompilerServices.TaskAwaiter`1.GetResult()
   at Microsoft.EntityFrameworkCore.Query.Internal.AsyncLinqOperatorProvider.ExceptionInterceptor`1.EnumeratorExceptionInterceptor.<MoveNext>d__5.MoveNext()
--- End of stack trace from previous location where exception was thrown ---
   at System.Runtime.ExceptionServices.ExceptionDispatchInfo.Throw()
   at System.Runtime.CompilerServices.TaskAwaiter.ThrowForNonSuccess(Task task)
   at System.Runtime.CompilerServices.TaskAwaiter.HandleNonSuccessAndDebuggerNotification(Task task)
   at System.Runtime.CompilerServices.TaskAwaiter`1.GetResult()
   at Microsoft.EntityFrameworkCore.Query.Internal.QueryCompiler.<ExecuteSingletonAsyncQuery>d__23`1.MoveNext()
2018-05-16T10:59:41.4965377+02:00 0HLDR17906P4L:00000003 [ERR] An unhandled exception has occurred while executing the request (cf926119)
System.AggregateException: One or more errors occurred. (A task was canceled.) ---> System.Threading.Tasks.TaskCanceledException: A task was canceled.
   --- End of inner exception stack trace ---
   at System.Threading.Tasks.Task.ThrowIfExceptional(Boolean includeTaskCanceledExceptions)
   at System.Threading.Tasks.Task`1.GetResultCore(Boolean waitCompletionNotification)
   at GirafRest.Models.DTOs.DepartmentDTO.<>c__DisplayClass18_0.<FindMembers>b__0(GirafUser m)
   at System.Linq.Enumerable.SelectListIterator`2.MoveNext()
   at System.Collections.Generic.List`1.AddEnumerable(IEnumerable`1 enumerable)
   at GirafRest.Models.DTOs.DepartmentDTO.FindMembers(IEnumerable`1 users, RoleManager`1 roleManager, IGirafService girafService)
   at GirafRest.Controllers.DepartmentController.<Get>d__5.MoveNext()
--- End of stack trace from previous location where exception was thrown ---
   at System.Runtime.ExceptionServices.ExceptionDispatchInfo.Throw()
   at System.Runtime.CompilerServices.TaskAwaiter.HandleNonSuccessAndDebuggerNotification(Task task)
   at lambda_method(Closure , Object )
   at Microsoft.Extensions.Internal.ObjectMethodExecutorAwaitable.Awaiter.GetResult()
   at Microsoft.AspNetCore.Mvc.Internal.ControllerActionInvoker.<InvokeActionMethodAsync>d__12.MoveNext()
--- End of stack trace from previous location where exception was thrown ---
   at System.Runtime.ExceptionServices.ExceptionDispatchInfo.Throw()
   at System.Runtime.CompilerServices.TaskAwaiter.HandleNonSuccessAndDebuggerNotification(Task task)
   at Microsoft.AspNetCore.Mvc.Internal.ControllerActionInvoker.<InvokeNextActionFilterAsync>d__10.MoveNext()
--- End of stack trace from previous location where exception was thrown ---
   at System.Runtime.ExceptionServices.ExceptionDispatchInfo.Throw()
   at Microsoft.AspNetCore.Mvc.Internal.ControllerActionInvoker.Rethrow(ActionExecutedContext context)
   at Microsoft.AspNetCore.Mvc.Internal.ControllerActionInvoker.Next(State& next, Scope& scope, Object& state, Boolean& isCompleted)
   at Microsoft.AspNetCore.Mvc.Internal.ControllerActionInvoker.<InvokeInnerFilterAsync>d__14.MoveNext()
--- End of stack trace from previous location where exception was thrown ---
   at System.Runtime.ExceptionServices.ExceptionDispatchInfo.Throw()
   at System.Runtime.CompilerServices.TaskAwaiter.HandleNonSuccessAndDebuggerNotification(Task task)
   at Microsoft.AspNetCore.Mvc.Internal.ResourceInvoker.<InvokeNextResourceFilter>d__22.MoveNext()
--- End of stack trace from previous location where exception was thrown ---
   at System.Runtime.ExceptionServices.ExceptionDispatchInfo.Throw()
   at Microsoft.AspNetCore.Mvc.Internal.ResourceInvoker.Rethrow(ResourceExecutedContext context)
   at Microsoft.AspNetCore.Mvc.Internal.ResourceInvoker.Next(State& next, Scope& scope, Object& state, Boolean& isCompleted)
   at Microsoft.AspNetCore.Mvc.Internal.ResourceInvoker.<InvokeFilterPipelineAsync>d__17.MoveNext()
--- End of stack trace from previous location where exception was thrown ---
   at System.Runtime.ExceptionServices.ExceptionDispatchInfo.Throw()
   at System.Runtime.CompilerServices.TaskAwaiter.HandleNonSuccessAndDebuggerNotification(Task task)
   at Microsoft.AspNetCore.Mvc.Internal.ResourceInvoker.<InvokeAsync>d__15.MoveNext()
--- End of stack trace from previous location where exception was thrown ---
   at System.Runtime.ExceptionServices.ExceptionDispatchInfo.Throw()
   at System.Runtime.CompilerServices.TaskAwaiter.HandleNonSuccessAndDebuggerNotification(Task task)
   at Microsoft.AspNetCore.Builder.RouterMiddleware.<Invoke>d__4.MoveNext()
--- End of stack trace from previous location where exception was thrown ---
   at System.Runtime.ExceptionServices.ExceptionDispatchInfo.Throw()
   at System.Runtime.CompilerServices.TaskAwaiter.HandleNonSuccessAndDebuggerNotification(Task task)
   at Microsoft.AspNetCore.Authentication.AuthenticationMiddleware.<Invoke>d__6.MoveNext()
--- End of stack trace from previous location where exception was thrown ---
   at System.Runtime.ExceptionServices.ExceptionDispatchInfo.Throw()
   at System.Runtime.CompilerServices.TaskAwaiter.HandleNonSuccessAndDebuggerNotification(Task task)
   at Swashbuckle.AspNetCore.SwaggerUI.SwaggerUIIndexMiddleware.<Invoke>d__3.MoveNext()
--- End of stack trace from previous location where exception was thrown ---
   at System.Runtime.ExceptionServices.ExceptionDispatchInfo.Throw()
   at System.Runtime.CompilerServices.TaskAwaiter.HandleNonSuccessAndDebuggerNotification(Task task)
   at Swashbuckle.AspNetCore.Swagger.SwaggerMiddleware.<Invoke>d__6.MoveNext()
--- End of stack trace from previous location where exception was thrown ---
   at System.Runtime.ExceptionServices.ExceptionDispatchInfo.Throw()
   at System.Runtime.CompilerServices.TaskAwaiter.HandleNonSuccessAndDebuggerNotification(Task task)
   at Microsoft.AspNetCore.Diagnostics.DeveloperExceptionPageMiddleware.<Invoke>d__7.MoveNext()
---> (Inner Exception #0) System.Threading.Tasks.TaskCanceledException: A task was canceled.<---

2018-05-16T11:15:06.3928573+02:00 0HLDR1EV7B6CB:00000013 [WRN] The LINQ expression '"where {from String ui in {from IdentityUserRole`1 u in value(Microsoft.EntityFrameworkCore.Query.Internal.EntityQueryable`1[Microsoft.AspNetCore.Identity.IdentityUserRole`1[System.String]]) where ([u].RoleId == __roleGuardianId_0) select [u].UserId => Distinct()} where ([ui] == [u].Id) select [ui] => Any()}"' could not be translated and will be evaluated locally. (011792c6)
2018-05-16T11:18:30.7700517+02:00 0HLDR1EV7B6CG:00000006 [ERR] An exception occurred in the database while iterating the results of a query for context type '"GirafRest.Data.GirafDbContext"'."
""System.NullReferenceException: Object reference not set to an instance of an object.
   at System.Linq.AsyncEnumerable.SelectEnumerableAsyncIterator`2.<MoveNextCore>d__7.MoveNext()
--- End of stack trace from previous location where exception was thrown ---
   at System.Runtime.ExceptionServices.ExceptionDispatchInfo.Throw()
   at System.Runtime.CompilerServices.TaskAwaiter.HandleNonSuccessAndDebuggerNotification(Task task)
   at System.Runtime.CompilerServices.ConfiguredTaskAwaitable`1.ConfiguredTaskAwaiter.GetResult()
   at System.Linq.AsyncEnumerable.AsyncIterator`1.<MoveNext>d__10.MoveNext()
--- End of stack trace from previous location where exception was thrown ---
   at System.Runtime.ExceptionServices.ExceptionDispatchInfo.Throw()
   at System.Runtime.CompilerServices.TaskAwaiter.HandleNonSuccessAndDebuggerNotification(Task task)
   at System.Runtime.CompilerServices.TaskAwaiter`1.GetResult()
   at Microsoft.EntityFrameworkCore.Query.Internal.AsyncLinqOperatorProvider.ExceptionInterceptor`1.EnumeratorExceptionInterceptor.<MoveNext>d__5.MoveNext()" (64e2593c)
System.NullReferenceException: Object reference not set to an instance of an object.
   at System.Linq.AsyncEnumerable.SelectEnumerableAsyncIterator`2.<MoveNextCore>d__7.MoveNext()
--- End of stack trace from previous location where exception was thrown ---
   at System.Runtime.ExceptionServices.ExceptionDispatchInfo.Throw()
   at System.Runtime.CompilerServices.TaskAwaiter.HandleNonSuccessAndDebuggerNotification(Task task)
   at System.Runtime.CompilerServices.ConfiguredTaskAwaitable`1.ConfiguredTaskAwaiter.GetResult()
   at System.Linq.AsyncEnumerable.AsyncIterator`1.<MoveNext>d__10.MoveNext()
--- End of stack trace from previous location where exception was thrown ---
   at System.Runtime.ExceptionServices.ExceptionDispatchInfo.Throw()
   at System.Runtime.CompilerServices.TaskAwaiter.HandleNonSuccessAndDebuggerNotification(Task task)
   at System.Runtime.CompilerServices.TaskAwaiter`1.GetResult()
   at Microsoft.EntityFrameworkCore.Query.Internal.AsyncLinqOperatorProvider.ExceptionInterceptor`1.EnumeratorExceptionInterceptor.<MoveNext>d__5.MoveNext()
2018-05-16T11:18:30.8164139+02:00 0HLDR1EV7B6CG:00000006 [ERR] An exception occurred in the database while iterating the results of a query for context type '"GirafRest.Data.GirafDbContext"'."
""System.NullReferenceException: Object reference not set to an instance of an object.
   at System.Linq.AsyncEnumerable.SelectEnumerableAsyncIterator`2.<MoveNextCore>d__7.MoveNext()
--- End of stack trace from previous location where exception was thrown ---
   at System.Runtime.ExceptionServices.ExceptionDispatchInfo.Throw()
   at System.Runtime.CompilerServices.TaskAwaiter.HandleNonSuccessAndDebuggerNotification(Task task)
   at System.Runtime.CompilerServices.ConfiguredTaskAwaitable`1.ConfiguredTaskAwaiter.GetResult()
   at System.Linq.AsyncEnumerable.AsyncIterator`1.<MoveNext>d__10.MoveNext()
--- End of stack trace from previous location where exception was thrown ---
   at System.Runtime.ExceptionServices.ExceptionDispatchInfo.Throw()
   at System.Runtime.CompilerServices.TaskAwaiter.HandleNonSuccessAndDebuggerNotification(Task task)
   at System.Runtime.CompilerServices.TaskAwaiter`1.GetResult()
   at Microsoft.EntityFrameworkCore.Query.Internal.AsyncLinqOperatorProvider.ExceptionInterceptor`1.EnumeratorExceptionInterceptor.<MoveNext>d__5.MoveNext()
--- End of stack trace from previous location where exception was thrown ---
   at System.Runtime.ExceptionServices.ExceptionDispatchInfo.Throw()
   at System.Runtime.CompilerServices.TaskAwaiter.HandleNonSuccessAndDebuggerNotification(Task task)
   at System.Runtime.CompilerServices.TaskAwaiter`1.GetResult()
   at Microsoft.EntityFrameworkCore.Query.Internal.QueryCompiler.<ExecuteSingletonAsyncQuery>d__23`1.MoveNext()" (64e2593c)
System.NullReferenceException: Object reference not set to an instance of an object.
   at System.Linq.AsyncEnumerable.SelectEnumerableAsyncIterator`2.<MoveNextCore>d__7.MoveNext()
--- End of stack trace from previous location where exception was thrown ---
   at System.Runtime.ExceptionServices.ExceptionDispatchInfo.Throw()
   at System.Runtime.CompilerServices.TaskAwaiter.HandleNonSuccessAndDebuggerNotification(Task task)
   at System.Runtime.CompilerServices.ConfiguredTaskAwaitable`1.ConfiguredTaskAwaiter.GetResult()
   at System.Linq.AsyncEnumerable.AsyncIterator`1.<MoveNext>d__10.MoveNext()
--- End of stack trace from previous location where exception was thrown ---
   at System.Runtime.ExceptionServices.ExceptionDispatchInfo.Throw()
   at System.Runtime.CompilerServices.TaskAwaiter.HandleNonSuccessAndDebuggerNotification(Task task)
   at System.Runtime.CompilerServices.TaskAwaiter`1.GetResult()
   at Microsoft.EntityFrameworkCore.Query.Internal.AsyncLinqOperatorProvider.ExceptionInterceptor`1.EnumeratorExceptionInterceptor.<MoveNext>d__5.MoveNext()
--- End of stack trace from previous location where exception was thrown ---
   at System.Runtime.ExceptionServices.ExceptionDispatchInfo.Throw()
   at System.Runtime.CompilerServices.TaskAwaiter.HandleNonSuccessAndDebuggerNotification(Task task)
   at System.Runtime.CompilerServices.TaskAwaiter`1.GetResult()
   at Microsoft.EntityFrameworkCore.Query.Internal.QueryCompiler.<ExecuteSingletonAsyncQuery>d__23`1.MoveNext()
2018-05-16T11:18:31.2453323+02:00 0HLDR1EV7B6CG:00000006 [ERR] An unhandled exception has occurred while executing the request (cf926119)
System.AggregateException: One or more errors occurred. (Object reference not set to an instance of an object.) ---> System.NullReferenceException: Object reference not set to an instance of an object.
   at System.Linq.AsyncEnumerable.SelectEnumerableAsyncIterator`2.<MoveNextCore>d__7.MoveNext()
--- End of stack trace from previous location where exception was thrown ---
   at System.Runtime.ExceptionServices.ExceptionDispatchInfo.Throw()
   at System.Runtime.CompilerServices.TaskAwaiter.HandleNonSuccessAndDebuggerNotification(Task task)
   at System.Runtime.CompilerServices.ConfiguredTaskAwaitable`1.ConfiguredTaskAwaiter.GetResult()
   at System.Linq.AsyncEnumerable.AsyncIterator`1.<MoveNext>d__10.MoveNext()
--- End of stack trace from previous location where exception was thrown ---
   at System.Runtime.ExceptionServices.ExceptionDispatchInfo.Throw()
   at System.Runtime.CompilerServices.TaskAwaiter.HandleNonSuccessAndDebuggerNotification(Task task)
   at System.Runtime.CompilerServices.TaskAwaiter`1.GetResult()
   at Microsoft.EntityFrameworkCore.Query.Internal.AsyncLinqOperatorProvider.ExceptionInterceptor`1.EnumeratorExceptionInterceptor.<MoveNext>d__5.MoveNext()
--- End of stack trace from previous location where exception was thrown ---
   at System.Runtime.ExceptionServices.ExceptionDispatchInfo.Throw()
   at System.Runtime.CompilerServices.TaskAwaiter.HandleNonSuccessAndDebuggerNotification(Task task)
   at System.Runtime.CompilerServices.TaskAwaiter`1.GetResult()
   at Microsoft.EntityFrameworkCore.Query.Internal.QueryCompiler.<ExecuteSingletonAsyncQuery>d__23`1.MoveNext()
--- End of stack trace from previous location where exception was thrown ---
   at System.Runtime.ExceptionServices.ExceptionDispatchInfo.Throw()
   at System.Runtime.CompilerServices.TaskAwaiter.HandleNonSuccessAndDebuggerNotification(Task task)
   at System.Runtime.CompilerServices.TaskAwaiter`1.GetResult()
   at Microsoft.AspNetCore.Identity.EntityFrameworkCore.UserStore`9.<IsInRoleAsync>d__37.MoveNext()
--- End of stack trace from previous location where exception was thrown ---
   at System.Runtime.ExceptionServices.ExceptionDispatchInfo.Throw()
   at System.Runtime.CompilerServices.TaskAwaiter.HandleNonSuccessAndDebuggerNotification(Task task)
   at System.Runtime.CompilerServices.TaskAwaiter`1.GetResult()
   at Microsoft.AspNetCore.Identity.UserManager`1.<IsInRoleAsync>d__111.MoveNext()
--- End of stack trace from previous location where exception was thrown ---
   at System.Runtime.ExceptionServices.ExceptionDispatchInfo.Throw()
   at System.Runtime.CompilerServices.TaskAwaiter.HandleNonSuccessAndDebuggerNotification(Task task)
   at System.Runtime.CompilerServices.TaskAwaiter`1.GetResult()
   at GirafRest.Extensions.GirafExtensions.<findUserRole>d__2.MoveNext()
   --- End of inner exception stack trace ---
   at System.Threading.Tasks.Task.ThrowIfExceptional(Boolean includeTaskCanceledExceptions)
   at System.Threading.Tasks.Task`1.GetResultCore(Boolean waitCompletionNotification)
   at GirafRest.Models.DTOs.DepartmentDTO.<>c__DisplayClass18_0.<FindMembers>b__0(GirafUser m)
   at System.Linq.Enumerable.SelectListIterator`2.MoveNext()
   at System.Collections.Generic.List`1.AddEnumerable(IEnumerable`1 enumerable)
   at GirafRest.Models.DTOs.DepartmentDTO.FindMembers(IEnumerable`1 users, RoleManager`1 roleManager, IGirafService girafService)
   at GirafRest.Controllers.DepartmentController.<Get>d__5.MoveNext()
--- End of stack trace from previous location where exception was thrown ---
   at System.Runtime.ExceptionServices.ExceptionDispatchInfo.Throw()
   at System.Runtime.CompilerServices.TaskAwaiter.HandleNonSuccessAndDebuggerNotification(Task task)
   at lambda_method(Closure , Object )
   at Microsoft.Extensions.Internal.ObjectMethodExecutorAwaitable.Awaiter.GetResult()
   at Microsoft.AspNetCore.Mvc.Internal.ControllerActionInvoker.<InvokeActionMethodAsync>d__12.MoveNext()
--- End of stack trace from previous location where exception was thrown ---
   at System.Runtime.ExceptionServices.ExceptionDispatchInfo.Throw()
   at System.Runtime.CompilerServices.TaskAwaiter.HandleNonSuccessAndDebuggerNotification(Task task)
   at Microsoft.AspNetCore.Mvc.Internal.ControllerActionInvoker.<InvokeNextActionFilterAsync>d__10.MoveNext()
--- End of stack trace from previous location where exception was thrown ---
   at System.Runtime.ExceptionServices.ExceptionDispatchInfo.Throw()
   at Microsoft.AspNetCore.Mvc.Internal.ControllerActionInvoker.Rethrow(ActionExecutedContext context)
   at Microsoft.AspNetCore.Mvc.Internal.ControllerActionInvoker.Next(State& next, Scope& scope, Object& state, Boolean& isCompleted)
   at Microsoft.AspNetCore.Mvc.Internal.ControllerActionInvoker.<InvokeInnerFilterAsync>d__14.MoveNext()
--- End of stack trace from previous location where exception was thrown ---
   at System.Runtime.ExceptionServices.ExceptionDispatchInfo.Throw()
   at System.Runtime.CompilerServices.TaskAwaiter.HandleNonSuccessAndDebuggerNotification(Task task)
   at Microsoft.AspNetCore.Mvc.Internal.ResourceInvoker.<InvokeNextResourceFilter>d__22.MoveNext()
--- End of stack trace from previous location where exception was thrown ---
   at System.Runtime.ExceptionServices.ExceptionDispatchInfo.Throw()
   at Microsoft.AspNetCore.Mvc.Internal.ResourceInvoker.Rethrow(ResourceExecutedContext context)
   at Microsoft.AspNetCore.Mvc.Internal.ResourceInvoker.Next(State& next, Scope& scope, Object& state, Boolean& isCompleted)
   at Microsoft.AspNetCore.Mvc.Internal.ResourceInvoker.<InvokeFilterPipelineAsync>d__17.MoveNext()
--- End of stack trace from previous location where exception was thrown ---
   at System.Runtime.ExceptionServices.ExceptionDispatchInfo.Throw()
   at System.Runtime.CompilerServices.TaskAwaiter.HandleNonSuccessAndDebuggerNotification(Task task)
   at Microsoft.AspNetCore.Mvc.Internal.ResourceInvoker.<InvokeAsync>d__15.MoveNext()
--- End of stack trace from previous location where exception was thrown ---
   at System.Runtime.ExceptionServices.ExceptionDispatchInfo.Throw()
   at System.Runtime.CompilerServices.TaskAwaiter.HandleNonSuccessAndDebuggerNotification(Task task)
   at Microsoft.AspNetCore.Builder.RouterMiddleware.<Invoke>d__4.MoveNext()
--- End of stack trace from previous location where exception was thrown ---
   at System.Runtime.ExceptionServices.ExceptionDispatchInfo.Throw()
   at System.Runtime.CompilerServices.TaskAwaiter.HandleNonSuccessAndDebuggerNotification(Task task)
   at Microsoft.AspNetCore.Authentication.AuthenticationMiddleware.<Invoke>d__6.MoveNext()
--- End of stack trace from previous location where exception was thrown ---
   at System.Runtime.ExceptionServices.ExceptionDispatchInfo.Throw()
   at System.Runtime.CompilerServices.TaskAwaiter.HandleNonSuccessAndDebuggerNotification(Task task)
   at Swashbuckle.AspNetCore.SwaggerUI.SwaggerUIIndexMiddleware.<Invoke>d__3.MoveNext()
--- End of stack trace from previous location where exception was thrown ---
   at System.Runtime.ExceptionServices.ExceptionDispatchInfo.Throw()
   at System.Runtime.CompilerServices.TaskAwaiter.HandleNonSuccessAndDebuggerNotification(Task task)
   at Swashbuckle.AspNetCore.Swagger.SwaggerMiddleware.<Invoke>d__6.MoveNext()
--- End of stack trace from previous location where exception was thrown ---
   at System.Runtime.ExceptionServices.ExceptionDispatchInfo.Throw()
   at System.Runtime.CompilerServices.TaskAwaiter.HandleNonSuccessAndDebuggerNotification(Task task)
   at Microsoft.AspNetCore.Diagnostics.DeveloperExceptionPageMiddleware.<Invoke>d__7.MoveNext()
---> (Inner Exception #0) System.NullReferenceException: Object reference not set to an instance of an object.
   at System.Linq.AsyncEnumerable.SelectEnumerableAsyncIterator`2.<MoveNextCore>d__7.MoveNext()
--- End of stack trace from previous location where exception was thrown ---
   at System.Runtime.ExceptionServices.ExceptionDispatchInfo.Throw()
   at System.Runtime.CompilerServices.TaskAwaiter.HandleNonSuccessAndDebuggerNotification(Task task)
   at System.Runtime.CompilerServices.ConfiguredTaskAwaitable`1.ConfiguredTaskAwaiter.GetResult()
   at System.Linq.AsyncEnumerable.AsyncIterator`1.<MoveNext>d__10.MoveNext()
--- End of stack trace from previous location where exception was thrown ---
   at System.Runtime.ExceptionServices.ExceptionDispatchInfo.Throw()
   at System.Runtime.CompilerServices.TaskAwaiter.HandleNonSuccessAndDebuggerNotification(Task task)
   at System.Runtime.CompilerServices.TaskAwaiter`1.GetResult()
   at Microsoft.EntityFrameworkCore.Query.Internal.AsyncLinqOperatorProvider.ExceptionInterceptor`1.EnumeratorExceptionInterceptor.<MoveNext>d__5.MoveNext()
--- End of stack trace from previous location where exception was thrown ---
   at System.Runtime.ExceptionServices.ExceptionDispatchInfo.Throw()
   at System.Runtime.CompilerServices.TaskAwaiter.HandleNonSuccessAndDebuggerNotification(Task task)
   at System.Runtime.CompilerServices.TaskAwaiter`1.GetResult()
   at Microsoft.EntityFrameworkCore.Query.Internal.QueryCompiler.<ExecuteSingletonAsyncQuery>d__23`1.MoveNext()
--- End of stack trace from previous location where exception was thrown ---
   at System.Runtime.ExceptionServices.ExceptionDispatchInfo.Throw()
   at System.Runtime.CompilerServices.TaskAwaiter.HandleNonSuccessAndDebuggerNotification(Task task)
   at System.Runtime.CompilerServices.TaskAwaiter`1.GetResult()
   at Microsoft.AspNetCore.Identity.EntityFrameworkCore.UserStore`9.<IsInRoleAsync>d__37.MoveNext()
--- End of stack trace from previous location where exception was thrown ---
   at System.Runtime.ExceptionServices.ExceptionDispatchInfo.Throw()
   at System.Runtime.CompilerServices.TaskAwaiter.HandleNonSuccessAndDebuggerNotification(Task task)
   at System.Runtime.CompilerServices.TaskAwaiter`1.GetResult()
   at Microsoft.AspNetCore.Identity.UserManager`1.<IsInRoleAsync>d__111.MoveNext()
--- End of stack trace from previous location where exception was thrown ---
   at System.Runtime.ExceptionServices.ExceptionDispatchInfo.Throw()
   at System.Runtime.CompilerServices.TaskAwaiter.HandleNonSuccessAndDebuggerNotification(Task task)
   at System.Runtime.CompilerServices.TaskAwaiter`1.GetResult()
   at GirafRest.Extensions.GirafExtensions.<findUserRole>d__2.MoveNext()<---

2018-05-16T11:19:56.8972970+02:00 0HLDR1EV7B6CR:00000001 [WRN] Change password failed for user "dea3cb05-537d-44c4-a537-a4c480634d99". (4e3cf999)
2018-05-16T11:20:02.2013203+02:00 0HLDR1EV7B6CR:00000002 [WRN] Change password failed for user "dea3cb05-537d-44c4-a537-a4c480634d99". (4e3cf999)
2018-05-16T11:20:28.5384284+02:00 0HLDR1EV7B6CR:00000005 [WRN] Change password failed for user "dea3cb05-537d-44c4-a537-a4c480634d99". (4e3cf999)
2018-05-16T11:20:35.1272074+02:00 0HLDR1EV7B6CR:00000006 [WRN] Change password failed for user "dea3cb05-537d-44c4-a537-a4c480634d99". (4e3cf999)
2018-05-16T11:21:25.7163659+02:00 0HLDR1EV7B6CS:0000000C [WRN] Invalid password for user "dea3cb05-537d-44c4-a537-a4c480634d99". (c2dce6c7)
2018-05-16T11:21:25.7494988+02:00 0HLDR1EV7B6CS:0000000C [WRN] User "dea3cb05-537d-44c4-a537-a4c480634d99" failed to provide the correct password. (ec8d2479)
2018-05-16T11:21:29.7500610+02:00 0HLDR1EV7B6CS:0000000D [WRN] Invalid password for user "dea3cb05-537d-44c4-a537-a4c480634d99". (c2dce6c7)
2018-05-16T11:21:29.7850361+02:00 0HLDR1EV7B6CS:0000000D [WRN] User "dea3cb05-537d-44c4-a537-a4c480634d99" failed to provide the correct password. (ec8d2479)
